2024-06-28 13:44:24,453 INFO    StreamThr :9907 [internal.py:wandb_internal():86] W&B internal server running at pid: 9907, started at: 2024-06-28 13:44:24.453054
2024-06-28 13:44:24,456 DEBUG   HandlerThread:9907 [handler.py:handle_request():144] handle_request: status
2024-06-28 13:44:24,462 INFO    WriterThread:9907 [datastore.py:open_for_write():85] open: /home/brett/Desktop/tutorials/ijepa/ijepa/wandb/run-20240628_134424-m0d8tm4v/run-m0d8tm4v.wandb
2024-06-28 13:44:24,462 DEBUG   SenderThread:9907 [sender.py:send():380] send: header
2024-06-28 13:44:24,476 DEBUG   SenderThread:9907 [sender.py:send():380] send: run
2024-06-28 13:44:24,652 ERROR   SenderThread:9907 [internal_api.py:execute():369] 404 response executing GraphQL.
2024-06-28 13:44:24,652 ERROR   SenderThread:9907 [internal_api.py:execute():370] {"errors":[{"message":"entity your_wandb_entity not found during upsertBucket","path":["upsertBucket"]}],"data":{"upsertBucket":null}}
2024-06-28 13:44:24,653 ERROR   SenderThread:9907 [sender.py:send_run():977] It appears that you do not have permission to access the requested resource. Please reach out to the project owner to grant you access. If you have the correct permissions, verify that there are no issues with your networking setup.(Error 404: Not Found)
Traceback (most recent call last):
  File "/home/brett/anaconda3/lib/python3.8/site-packages/wandb/sdk/lib/retry.py", line 131, in __call__
    result = self._call_fn(*args, **kwargs)
  File "/home/brett/anaconda3/lib/python3.8/site-packages/wandb/sdk/internal/internal_api.py", line 366, in execute
    return self.client.execute(*args, **kwargs)  # type: ignore
  File "/home/brett/anaconda3/lib/python3.8/site-packages/wandb/vendor/gql-0.2.0/wandb_gql/client.py", line 52, in execute
    result = self._get_result(document, *args, **kwargs)
  File "/home/brett/anaconda3/lib/python3.8/site-packages/wandb/vendor/gql-0.2.0/wandb_gql/client.py", line 60, in _get_result
    return self.transport.execute(document, *args, **kwargs)
  File "/home/brett/anaconda3/lib/python3.8/site-packages/wandb/sdk/lib/gql_request.py", line 59, in execute
    request.raise_for_status()
  File "/home/brett/anaconda3/lib/python3.8/site-packages/requests/models.py", line 1021, in raise_for_status
    raise HTTPError(http_error_msg, response=self)
requests.exceptions.HTTPError: 404 Client Error: Not Found for url: https://api.wandb.ai/graphql

During handling of the above exception, another exception occurred:

Traceback (most recent call last):
  File "/home/brett/anaconda3/lib/python3.8/site-packages/wandb/sdk/internal/sender.py", line 975, in send_run
    self._init_run(run, config_value_dict)
  File "/home/brett/anaconda3/lib/python3.8/site-packages/wandb/sdk/internal/sender.py", line 1013, in _init_run
    server_run, inserted, server_messages = self._api.upsert_run(
  File "/home/brett/anaconda3/lib/python3.8/site-packages/wandb/apis/normalize.py", line 73, in wrapper
    raise err
  File "/home/brett/anaconda3/lib/python3.8/site-packages/wandb/apis/normalize.py", line 41, in wrapper
    return func(*args, **kwargs)
  File "/home/brett/anaconda3/lib/python3.8/site-packages/wandb/sdk/internal/internal_api.py", line 2007, in upsert_run
    response = self.gql(
  File "/home/brett/anaconda3/lib/python3.8/site-packages/wandb/sdk/internal/internal_api.py", line 338, in gql
    ret = self._retry_gql(
  File "/home/brett/anaconda3/lib/python3.8/site-packages/wandb/sdk/lib/retry.py", line 147, in __call__
    retry_timedelta_triggered = check_retry_fn(e)
  File "/home/brett/anaconda3/lib/python3.8/site-packages/wandb/util.py", line 964, in check_retry_fn
    return fallback_retry_fn(e)
  File "/home/brett/anaconda3/lib/python3.8/site-packages/wandb/util.py", line 906, in no_retry_auth
    raise CommError(
wandb.errors.CommError: It appears that you do not have permission to access the requested resource. Please reach out to the project owner to grant you access. If you have the correct permissions, verify that there are no issues with your networking setup.(Error 404: Not Found)
2024-06-28 13:44:24,809 DEBUG   HandlerThread:9907 [handler.py:handle_request():144] handle_request: shutdown
2024-06-28 13:44:24,809 INFO    HandlerThread:9907 [handler.py:finish():844] shutting down handler
2024-06-28 13:44:25,476 INFO    WriterThread:9907 [datastore.py:close():294] close: /home/brett/Desktop/tutorials/ijepa/ijepa/wandb/run-20240628_134424-m0d8tm4v/run-m0d8tm4v.wandb
2024-06-28 13:44:25,670 INFO    SenderThread:9907 [sender.py:finish():1534] shutting down sender
